{"name": "test_failure", "status": "failed", "statusDetails": {"message": "AssertionError: assert False", "trace": "def test_failure():\n        \"\"\"this test fails\"\"\"\n>       assert False\nE       assert False\n\ntest_1.py:10: AssertionError"}, "description": "this test fails", "start": 1609570598814, "stop": 1609570598816, "uuid": "6ea58f34-932f-4849-ac00-0cd393db44e5", "historyId": "ce26ea326f6a76048ac3de9b6d69f276", "testCaseId": "f2de1d9ed43897e9bafd3992e3d69833", "fullName": "test_1#test_failure", "labels": [{"name": "suite", "value": "test_1"}, {"name": "host", "value": "PC-20150415WRCK"}, {"name": "thread", "value": "3504-MainThread"}, {"name": "framework", "value": "pytest"}, {"name": "language", "value": "cpython3"}, {"name": "package", "value": "test_1"}]}