{"name": "test_failure", "status": "failed", "statusDetails": {"message": "AssertionError: assert False", "trace": "def test_failure():\n        \"\"\"this test fails\"\"\"\n>       assert False\nE       assert False\n\ntest_1.py:10: AssertionError"}, "description": "this test fails", "start": 1609039104470, "stop": 1609039104471, "uuid": "df8fefd3-07fc-4608-a622-6e2703578063", "historyId": "ce26ea326f6a76048ac3de9b6d69f276", "testCaseId": "f2de1d9ed43897e9bafd3992e3d69833", "fullName": "test_1#test_failure", "labels": [{"name": "suite", "value": "test_1"}, {"name": "host", "value": "PC-20150415WRCK"}, {"name": "thread", "value": "6544-MainThread"}, {"name": "framework", "value": "pytest"}, {"name": "language", "value": "cpython3"}, {"name": "package", "value": "test_1"}]}